Workbook

Sheet Livros na Estante
A1: Nome | B1: Autor | C1: Editora | D1: ISBN | E1: Ano-Compra | F1: Lido
A2: 1984 | B2: George Orwell | C2: Clube de Literatura Clássica | E2: 2023 | F2: Sim
A3: Coração das Trevas | B3: Joseph Conrad | C3: Clube de Literatura Clássica | E3: 2023 | F3: Abandonado
A4: Contos do Grotesco e do Arabesco | B4: Edgar Allan Poe | C4: Clube de Literatura Clássica | E4: 2023 | F4: Abandonado
A5: Don Juan | B5: Lord Byron | C5: Clube de Literatura Clássica | D5: 978-658-7036-75-5 | E5: 2023 | F5: Não
A6: O Finado Mattia Pascal | B6: Luigi Pirandello | C6: Clube de Literatura Clássica | D6: 978-65-87036-76-2 | E6: 2023 | F6: Não
A7: A Conciência de Zeno | B7: Italo Svevo | C7: Clube de Literatura Clássica | E7: 2023 | F7: Não
A8: Fábulas de Esopo | B8: Esopo | C8: Clube de Literatura Clássica | D8: 978-65-87036-88-5 | E8: 2023 | F8: Não
A9: Ilusões Perdidas | B9: Honoré de Balzac | C9: Clube de Literatura Clássica | D9: 978-65-87036-74-8 | E9: 2023 | F9: Não
A10: Jerusalem Libertada | B10: Torquato Tasso | C10: Clube de Literatura Clássica | D10: 978-65-87036-33-5 | E10: 2023 | F10: Não
A11: Saga de Njall | B11: Anônimo | C11: Clube de Literatura Clássica | E11: 2023 | F11: Não
A12: Um Diário do Ano da Peste | B12: Daniel Defoe | C12: Clube de Literatura Clássica | E12: 2023 | F12: Não
A13: Madame Bovary | B13: Gustave Flaubert | C13: Clube de Literatura Clássica | D13: 978-65-87036-71-7 | E13: 2023 | F13: Não
A14: Os Trabalhadores do Mar | B14: Victor Hugo | C14: Clube de Literatura Clássica | D14: 978-65-87036-38-0 | E14: 2023 | F14: Não
A15: Crime e Castigo | B15: Fiódor Dostoiévski | C15: Clube de Literatura Clássica | D15: 978-65-87036-14-4 | E15: 2023 | F15: Não
A16: Irmãos Karamazov | B16: Fiódor Dostoiévski | C16: Clube de Literatura Clássica | E16: 2023 | F16: Não
A17: Pais e Filhos | B17: Ivan Turguêniev | C17: Clube de Literatura Clássica | D17: 978-65-87036-82-3 | E17: 2023 | F17: Não
A18: Memorias Póstumas de Brás Cubas | B18: Machado de Assis | C18: Clube de Literatura Clássica | D18: 978-65-87036-64-9 | E18: 2023 | F18: Não
A19: Dom Casmurro | B19: Machado de Assis | C19: Clube de Literatura Clássica | D19: 978-65-87036-03-8 | E19: 2023 | F19: Sim
A20: Caetés | B20: Graciliano Ramos | C20: Clube de Literatura Clássica | E20: 2023 | F20: Não
A21: São Bernardo | B21: Graciliano Ramos | C21: Clube de Literatura Clássica | E21: 2023 | F21: Não
A22: Angústia* | B22: Graciliano Ramos | C22: Clube de Literatura Clássica | E22: 2023 | F22: Não
A23: Vidas Secas | B23: Graciliano Ramos | C23: Clube de Literatura Clássica | E23: 2023 | F23: Sim
A24: Viagem ao Redor do meu Quarto | B24: Xavier de Maistre | C24: Clube de Literatura Clássica | E24: 2023 | F24: Não
A25: Contos do Casmurro | B25: Machado de Assis | C25: Clube de Literatura Clássica | E25: 2023 | F25: Não
A26: Saga de Gunnlaugr Lingua-de-Serpente | B26: Anônimo | C26: Clube de Literatura Clássica | E26: 2023 | F26: Não
A27: Vida de Esopo | B27: Anônimo | C27: Clube de Literatura Clássica | E27: 2023 | F27: Não
A28: A Conciência de Svevo | B28: Italo Svevo | C28: Clube de Literatura Clássica | E28: 2023 | F28: Não
A29: Diário de um Homem Superfluo | B29: Ivan Turguêniev | C29: Clube de Literatura Clássica | E29: 2023 | F29: Não
A30: A fazenda dos Animais | B30: George Orwell | C30: Clube de Literatura Clássica | E30: 2023 | F30: Sim
A31: Torquato Tasso | B31: Johann Wolfgang von Goethe | C31: Clube de Literatura Clássica | D31: 978-65-87036-34-2 | E31: 2023 | F31: Não
A32: Três contos | B32: Gustave Flaubert | C32: Clube de Literatura Clássica | D32: 978-65-87036-72-4 | E32: 2023 | F32: Não
A33: Eureka | B33: Edgar Allan Poe | C33: Clube de Literatura Clássica | E33: 2023 | F33: Não
A34: O Último Dia de um Condenado | B34: Victor Hugo | C34: Clube de Literatura Clássica | E34: 2023 | F34: Não
A35: A Peste Escarlate | B35: Jack London | C35: Clube de Literatura Clássica | D35: 978-65-87036-26-7 | E35: 2023 | F35: Não
A36: Seis Personagens em Busca de um Autor | B36: Luigi Pirandello | C36: Clube de Literatura Clássica | E36: 2023 | F36: Não
A37: Cadernos do Subterraneo | B37: Fiódor Dostoiévski | C37: Clube de Literatura Clássica | E37: 2023 | F37: Não
A38: Juventude | B38: Joseph Conrad | C38: Clube de Literatura Clássica | E38: 2023 | F38: Não
A39: Auto da Barca do Inferno | B39: Gil Vicente | C39: L&PM | F39: Sim
A40: O Caçador de Pipas | B40: Khaled Hosseini | C40: Nova Fronteira | F40: Não
...

Sheet Lidos
A1: Nome | B1: Autor | C1: Data de Leitura | D1: Status na Estante | E1: Coluna1
A2: Merlin, o Mágico | B2: Anônimo | C2: 35796 | D2: Sumiu
A3: Patolino | C3: 35796 | D3: Sumiu
A4: A Princesa e a Ervilha | B4: Sérgio Luiz de Oliveira Silva | C4: 36161 | D4: Sumiu
A5: Mini Livro Jó | C5: 36161 | D5: Sumiu
A6: Mini Livro Pastor | C6: 36161 | D6: Sumiu
A7: Bisa Bia, Bisa Bel | B7: Ana Maria Machado | C7: 37257 | D7: Sumiu
A8: Contos de Fadas Capa vermelha | C8: 37257 | D8: Sumiu
A9: Carta errante, avó atrapalhada, menina aniversariante | B9: Mirna Pinsky | C9: 37347 | D9: Estante
A10: Harry Potter e a Pedra Filosofal | B10: J. K. Rowling | C10: 37987 | D10: Emprestado | E10: Plínio
A11: Harry Potter e a Câmara Secreta | B11: J. K. Rowling | C11: 37987 | D11: Emprestado | E11: Plínio
A12: Um rio que vem da Grécia | B12: Cláudio Moreno | C12: 38353 | D12: Doado
A13: Harry Potter e o Prisioneiro de Azkaban | B13: J. K. Rowling | C13: 38353 | D13: Emprestado | E13: Plínio
A14: Brida | B14: Paulo Coelho | C14: 38353 | D14: Emprestado | E14: Larissa
A15: Ciclo de Avalon - As Brumas de Avalon - A Senhora da Magia | B15: Marion Zimmer Bradley | C15: 38718 | D15: Emprestado | E15: Larissa
A16: Ciclo de Avalon - As Brumas de Avalon - A Grande Rainha | B16: Marion Zimmer Bradley | C16: 38718 | D16: Emprestado | E16: Larissa
A17: Harry Potter e o Cálice de Fogo | B17: J. K. Rowling | C17: 39083 | D17: Emprestado | E17: Plínio
A18: Harry Potter e a Ordem da Fênix | B18: J. K. Rowling | C18: 39083 | D18: Emprestado | E18: Plínio
A19: Harry Potter e o Enigma do Príncipe | B19: J. K. Rowling | C19: 39083 | D19: Emprestado | E19: Plínio
A20: Ciclo de Avalon - As Brumas de Avalon - O Prisioneiro da Árvore | B20: Marion Zimmer Bradley | C20: 39083 | D20: Emprestado | E20: Larissa
A21: Ciclo de Avalon - As Brumas de Avalon - O Gamo-Rei | B21: Marion Zimmer Bradley | C21: 39083 | D21: Emprestado | E21: Larissa
A22: Harry Potter e as Relíquias da Morte | B22: J. K. Rowling | C22: 39448 | D22: Emprestado | E22: Plínio
A23: As Primaveras (1867) | B23: Casimiro Jose Marques de Abreu | C23: 39448 | D23: Doado
A24: Ramsés: O filho da luz | B24: Christian Jacq | C24: 39448 | D24: Emprestado | E24: Plínio
A25: Ramsés: O Templo de Milhões de Anos | B25: Christian Jacq | C25: 39448 | D25: Emprestado | E25: Plínio
A26: Mulheres que mudaram o mundo | B26: Gabriel Chalita | C26: 39448 | D26: Doado
A27: Sutras Sagradas | B27: Masaharu Taniguchi | C27: 39448 | D27: Estante
A28: "Shinsokan" e outras orações | B28: Masaharu Taniguchi | C28: 39448 | D28: Estante
A29: O Menino do Dedo Verde | B29: Maurice Druon | C29: 39448 | D29: Estante
A30: Pela porta do coração | B30: Regina Coeli Rennó | C30: 39448 | D30: Estante
A31: Só é gordo quem quer | B31: Uchôa Junior | C31: 39448 | D31: A venda
A32: Pelas Portas Do Coração | B32: Zíbia Gasparetto | C32: 39448 | D32: Estante
A33: Laços Eternos | B33: Zíbia Gasparetto | C33: 39448 | D33: Biblioteca | E33: Irradiação
A34: O Amor Venceu | B34: Zíbia Gasparetto | C34: 39448 | D34: Biblioteca | E34: Irradiação
A35: Entre o Amor e a Guerra | B35: Zíbia Gasparetto | C35: 39448 | D35: Biblioteca | E35: Irradiação
A36: A Casa | B36: André Vianco | C36: 39814 | D36: Emprestado | E36: Plínio
A37: O Alquimista | B37: Paulo Coelho | C37: 39814 | D37: Estante
A38: A Cabana | B38: William P. Young | C38: 39814 | D38: Emprestado | E38: Plínio
A39: Ciclo de Avalon - A Sacerdotisa de Avalon | B39: Marion Zimmer Bradley | C39: 40179 | D39: Biblioteca | E39: IFG
A40: O Livro dos Jovens | B40: Masaharu Taniguchi | C40: 40179 | D40: Doado
...

Sheet Estatisticas de Leitura
A1: Status de Leitura | B1: Quantidade
A2: Sim | B2: =COUNTIF('Livros na Estante'!F2:F1005,"Sim") -> 120 | C2: =B2/$B$7 -> 0.36923077
A3: Não | B3: =COUNTIF('Livros na Estante'!F2:F1005,"Não") -> 189 | C3: =B3/$B$7 -> 0.58153846
A4: Abandonado | B4: =COUNTIF('Livros na Estante'!F2:F1005,"Abandonado") -> 13 | C4: =B4/$B$7 -> 0.04
A5: Lendo | B5: =COUNTIF('Livros na Estante'!F2:F1005,"Lendo") -> 2 | C5: =B5/$B$7 -> 0.0061538462
A6: Relendo | B6: =COUNTIF('Livros na Estante'!F2:F1005,"Relendo") -> 1 | C6: =B6/$B$7 -> 0.0030769231
A7: Total | B7: =SUM(B2:B6) -> 325
A19: Status Lidos | B19: Quantidade | C19: %
A20: Estante | B20: =COUNTIF(Lidos!D:D,A20) -> 109 | C20: =IFERROR(B20/$B$27,0) -> 0.39636364
A21: Emprestado | B21: =COUNTIF(Lidos!D:D,A21) -> 68 | C21: =IFERROR(B21/$B$27,0) -> 0.24727273
A22: Biblioteca | B22: =COUNTIF(Lidos!D:D,A22) -> 61 | C22: =IFERROR(B22/$B$27,0) -> 0.22181818
A23: Doado | B23: =COUNTIF(Lidos!D:D,A23) -> 14 | C23: =IFERROR(B23/$B$27,0) -> 0.050909091
A24: Vendido | B24: =COUNTIF(Lidos!D:D,A24) -> 2 | C24: =IFERROR(B24/$B$27,0) -> 0.0072727273
A25: A venda | B25: =COUNTIF(Lidos!D:D,A25) -> 11 | C25: =IFERROR(B25/$B$27,0) -> 0.04
A26: Sumiu | B26: =COUNTIF(Lidos!D:D,A26) -> 10 | C26: =IFERROR(B26/$B$27,0) -> 0.036363636
A27: Total | B27: =SUM(B20:B26) -> 275

Sheet Ano compra
A3: Rótulos de Linha | B3: Contagem de Nome
A4: 2015 | B4: 3
A5: 2018 | B5: 10
A6: 2019 | B6: 2
A7: 2020 | B7: 8
A8: 2022 | B8: 10
A9: 2023 | B9: 45
A10: 2024 | B10: 7
A11: 2025 | B11: 15
A12: 2026 | B12: 76
A13: (vazio) | B13: 149
A14: Total Geral | B14: 325

Sheet Autores
A3: Rótulos de Linha | B3: Contagem de Nome
A4: Adam Silvera | B4: 1
A5: Adriana Carranca | B5: 1
A6: Agatha Christie | B6: 7
A7: Ai Yazawa | B7: 5
A8: Aldous Huxley | B8: 1
A9: Aleksandr Grin | B9: 1
A10: Alex Michaelides | B10: 1
A11: Alexandre Dumas | B11: 2
A12: Allan Kardec | B12: 1
A13: Ana Beatriz Barbosa Silva | B13: 1
A14: Ana Claudia Quintana Arantes | B14: 1
A15: Anônimo | B15: 10
... A151: Ziraldo | B151: 1
A152: (vazio)
A153: Yuval Noah Harari | B153: 2
A154: Mamede Mustafa Jarouche | B154: 5
A155: José Saramago | B155: 1
A156: Hans Christian Andersen | B156: 1
A157: Neil Gaiman | B157: 1
A158: Johanna Spyri | B158: 1
A159: Lemony Snicket | B159: 13
A160: Roger Zelazny | B160: 10
A161: Total Geral | B161: 325

Sheet Editora
A3: Rótulos de Linha | B3: Contagem de Nome
A4: Alfaguara | B4: 2
A5: Argumento | B5: 1
A6: Arqueiro | B6: 4
A7: Bertrand Brasil | B7: 2
A8: Biblioteca Azul | B8: 5
A9: Clube de Literatura Clássica | B9: 37
A10: Companhia das Letras | B10: 4
A11: Companhia das Letras | B11: 2
A12: Companhia das Letrinhas | B12: 1
A13: Darkside | B13: 8
A14: Edição do Autor | B14: 2
A15: FDT | B15: 1
... A51: Total Geral | B51: 325

Sheet Lidos Ano
A3: Rótulos de Linha | B3: Contagem de Data de Leitura
A4: <01/01/1998
A5: 1998 | B5: 2
A6: 1999 | B6: 3
A7: 2002 | B7: 3
A8: 2004 | B8: 2
A9: 2005 | B9: 3
A10: 2006 | B10: 2
A11: 2007 | B11: 5
A12: 2008 | B12: 14
A13: 2009 | B13: 3
A14: 2010 | B14: 5
A15: 2012 | B15: 6
A16: 2013 | B16: 14
... A30: Total Geral | B30: 274

Sheet Séries Incompletas
A1: Nome
A3: Fronteiras do universo
A4: Nana
A5: Mundo de tinta
A6: Jogos Vorazes
A7: Herois do Olimpo
A8: Millenium
A9: Ciclo de Avalon
A10: Rangers
A11: As cronicas de Anne
A12: Hainish Cycle
A13: Vampiratas
A14: A cronica do Matador de Rei
